Workbook

Sheet Contents
B2: Supplementary Information for: Experts find influential assumptions in global irrigation models to have limited epistemic strength
B4: Authors: Seth N. Linga*, Carmen Aguiló-Rivera, Olivia Richards, Samuel Flinders, Joshua Larsen, Michela Massimi, Giovanni De Grandis, José María García Avilés, and Arnald Puy
B5: * Corresponding Author
B6: Email address: sxl1405@student.bham.ac.uk
B8: TABLE | C8: DESCRIPTION
B9: Table S1 | C9: The spreadsheet compiles assumptions in global irrigation models, detailing their empirical nature, classification within irrigation domains, and justification for each categorisation.

Sheet ranking
A1: code | B1: assumption | C1: nature | D1: e1 | E1: e2 | F1: e3 | G1: e4 | H1: e5 | I1: e6 | J1: e7 | K1: e8 | L1: e9 | M1: e10 | N1: e11
A2: A1 | B2: Irrigated crops can be represented as discrete crop types. | C2: Empirical | D2: 0 | E2: 0 | F2: 0 | G2: 0 | H2: 0 | I2: 0 | J2: 0 | K2: 0 | L2: 0 | M2: 0 | N2: 0
A3: A2 | B3: Irrigated crops can be represented as rice and non-rice. | C3: Pragmatic | D3: 0 | E3: 0 | F3: 0 | G3: 2 | H3: 0 | I3: 0 | J3: 0 | K3: 0 | L3: 0 | M3: 0 | N3: 0
A4: A3 | B4: Types of irrigated crops are limited to less than 10. | C4: Pragmatic | D4: 0 | E4: 0 | F4: 0 | G4: 0 | H4: 0 | I4: 0 | J4: 0 | K4: 0 | L4: 0 | M4: 0 | N4: 0
A5: A4 | B5: An area with mixed cropping can be treated as an area with one single crop. | C5: Pragmatic | D5: 0 | E5: 0 | F5: 0 | G5: 0 | H5: 0 | I5: 0 | J5: 0 | K5: 0 | L5: 0 | M5: 4 | N5: 0
A6: A5 | B6: Farmers select the cultivar best adapted to the local environment. | C6: Pragmatic | D6: 0 | E6: 0 | F6: 0 | G6: 0 | H6: 0 | I6: 0 | J6: 0 | K6: 0 | L6: 0 | M6: 0 | N6: 0
A7: A6 | B7: Temperate cereals can be grown during summer. | C7: Pragmatic | D7: 0 | E7: 0 | F7: 0 | G7: 0 | H7: 0 | I7: 0 | J7: 0 | K7: 0 | L7: 0 | M7: 0 | N7: 0
A8: A7 | B8: The primary crop is planted during the first season, followed by the secondary crop. | C8: Pragmatic | D8: 0 | E8: 0 | F8: 0 | G8: 0 | H8: 0 | I8: 0 | J8: 0 | K8: 0 | L8: 0 | M8: 0 | N8: 0
A9: A8 | B9: Rice is grown twice per year. | C9: Pragmatic | D9: 0 | E9: 0 | F9: 8 | G9: 0 | H9: 0 | I9: 0 | J9: 0 | K9: 0 | L9: 0 | M9: 0 | N9: 0
A10: A9 | B10: The same crops are grown in the same places every year. | C10: Pragmatic | D10: 0 | E10: 0 | F10: 0 | G10: 0 | H10: 0 | I10: 0 | J10: 0 | K10: 0 | L10: 0 | M10: 0 | N10: 0
A11: A10 | B11: A single dataset can be used to represent the distribution of crop types. | C11: Pragmatic | D11: 6 | E11: 0 | F11: 0 | G11: 0 | H11: 0 | I11: 0 | J11: 9 | K11: 9 | L11: 9 | M11: 0 | N11: 0
A12: A11 | B12: A single dataset can be used to represent the proportion of irrigated lands. | C12: Pragmatic | D12: 5 | E12: 10 | F12: 5 | G12: 8 | H12: 8 | I12: 0 | J12: 10 | K12: 10 | L12: 10 | M12: 5 | N12: 10
A13: A12 | B13: All crops are harvested within one year. | C13: Pragmatic | D13: 0 | E13: 0 | F13: 0 | G13: 0 | H13: 0 | I13: 0 | J13: 0 | K13: 0 | L13: 0 | M13: 0 | N13: 0
... A101: E11 | B101: No fixed priority is given to any sector; instead, all sectors compete equally for available water. | C101: Pragmatic | D101: 0 | E101: 0 | F101: 0 | G101: 0 | H101: 0 | I101: 0 | J101: 0 | K101: 4 | L101: 0 | M101: 0 | N101: 0

Sheet pedigree_mod
A1: expert_id | B1: code | C1: assumption | D1: criterion | E1: score
A2: 1 | B2: A11 | C2: =VLOOKUP(B2, ranking!A:B, 2, FALSE) -> A single dataset can be used to represent the proportion of irrigated lands. | D2: limitations | E2: 1
A3: 1 | B3: A11 | C3: =VLOOKUP(B3, ranking!A:B, 2, FALSE) -> A single dataset can be used to represent the proportion of irrigated lands. | D3: plausibility | E3: 2
A4: 1 | B4: A11 | C4: =VLOOKUP(B4, ranking!A:B, 2, FALSE) -> A single dataset can be used to represent the proportion of irrigated lands. | D4: choice_space | E4: 2
A5: 1 | B5: A11 | C5: =VLOOKUP(B5, ranking!A:B, 2, FALSE) -> A single dataset can be used to represent the proportion of irrigated lands. | D5: peer_agreement | E5: 2
A6: 1 | B6: A11 | C6: =VLOOKUP(B6, ranking!A:B, 2, FALSE) -> A single dataset can be used to represent the proportion of irrigated lands. | D6: influence | E6: 3
A7: 1 | B7: B31 | C7: =VLOOKUP(B7, ranking!A:B, 2, FALSE) -> A single number can represent the irrigation efficiency over a region or country. | D7: limitations | E7: 0
A8: 1 | B8: B31 | C8: =VLOOKUP(B8, ranking!A:B, 2, FALSE) -> A single number can represent the irrigation efficiency over a region or country. | D8: plausibility | E8: 0
A9: 1 | B9: B31 | C9: =VLOOKUP(B9, ranking!A:B, 2, FALSE) -> A single number can represent the irrigation efficiency over a region or country. | D9: choice_space | E9: 3
A10: 1 | B10: B31 | C10: =VLOOKUP(B10, ranking!A:B, 2, FALSE) -> A single number can represent the irrigation efficiency over a region or country. | D10: peer_agreement | E10: 2
A11: 1 | B11: B31 | C11: =VLOOKUP(B11, ranking!A:B, 2, FALSE) -> A single number can represent the irrigation efficiency over a region or country. | D11: influence | E11: 3
A12: 1 | B12: A10 | C12: =VLOOKUP(B12, ranking!A:B, 2, FALSE) -> A single dataset can be used to represent the distribution of crop types. | D12: limitations | E12: 1
A13: 1 | B13: A10 | C13: =VLOOKUP(B13, ranking!A:B, 2, FALSE) -> A single dataset can be used to represent the distribution of crop types. | D13: plausibility | E13: 2
... A365: 8 | B365: A10 | C365: =VLOOKUP(B365, ranking!A:B, 2, FALSE) -> A single dataset can be used to represent the distribution of crop types. | D365: peer_agreement | E365: 3
A366: 8 | B366: A10 | C366: =VLOOKUP(B366, ranking!A:B, 2, FALSE) -> A single dataset can be used to represent the distribution of crop types. | D366: influence
A367: 8 | B367: C12 | C367: =VLOOKUP(B367, ranking!A:B, 2, FALSE) -> Crops in irrigated areas always receive their full water requirement. | D367: limitations | E367: 2
A368: 8 | B368: C12 | C368: =VLOOKUP(B368, ranking!A:B, 2, FALSE) -> Crops in irrigated areas always receive their full water requirement. | D368: plausibility | E368: 0
A369: 8 | B369: C12 | C369: =VLOOKUP(B369, ranking!A:B, 2, FALSE) -> Crops in irrigated areas always receive their full water requirement. | D369: choice_space | E369: 0
A370: 8 | B370: C12 | C370: =VLOOKUP(B370, ranking!A:B, 2, FALSE) -> Crops in irrigated areas always receive their full water requirement. | D370: peer_agreement | E370: 1
A371: 8 | B371: C12 | C371: =VLOOKUP(B371, ranking!A:B, 2, FALSE) -> Crops in irrigated areas always receive their full water requirement. | D371: influence | E371: 3
A372: 8 | B372: B22 | C372: =VLOOKUP(B372, ranking!A:B, 2, FALSE) -> Irrigation delivery is efficient. | D372: limitations | E372: 2
A373: 8 | B373: B22 | C373: =VLOOKUP(B373, ranking!A:B, 2, FALSE) -> Irrigation delivery is efficient. | D373: plausibility | E373: 0
A374: 8 | B374: B22 | C374: =VLOOKUP(B374, ranking!A:B, 2, FALSE) -> Irrigation delivery is efficient. | D374: choice_space | E374: 0
A375: 8 | B375: B22 | C375: =VLOOKUP(B375, ranking!A:B, 2, FALSE) -> Irrigation delivery is efficient. | D375: peer_agreement | E375: 2
A376: 8 | B376: B22 | C376: =VLOOKUP(B376, ranking!A:B, 2, FALSE) -> Irrigation delivery is efficient. | D376: influence | E376: 3
A377: 8 | B377: E2 | C377: =VLOOKUP(B377, ranking!A:B, 2, FALSE) -> Water supply for irrigation is unconstrained; unlimited to meet irrigation demand. | D377: limitations | E377: 1
A378: 8 | B378: E2 | C378: =VLOOKUP(B378, ranking!A:B, 2, FALSE) -> Water supply for irrigation is unconstrained; unlimited to meet irrigation demand. | D378: plausibility | E378: 1
... A551: 11 | B551: E1 | C551: =VLOOKUP(B551, ranking!A:B, 2, FALSE) -> Water supply for irrigation is constrained to local sources. | D551: influence | E551: 2

Sheet pedigree_comb
A1: expert_id | B1: code | C1: assumption | D1: criterion | E1: score
A2: 1 | B2: A11 | C2: =VLOOKUP(B2, ranking!A:B, 2, FALSE) -> A single dataset can be used to represent the proportion of irrigated lands. | D2: limitations | E2: 1
A3: 1 | B3: A11 | C3: =VLOOKUP(B3, ranking!A:B, 2, FALSE) -> A single dataset can be used to represent the proportion of irrigated lands. | D3: plausibility | E3: 2
A4: 1 | B4: A11 | C4: =VLOOKUP(B4, ranking!A:B, 2, FALSE) -> A single dataset can be used to represent the proportion of irrigated lands. | D4: choice_space | E4: 2
A5: 1 | B5: A11 | C5: =VLOOKUP(B5, ranking!A:B, 2, FALSE) -> A single dataset can be used to represent the proportion of irrigated lands. | D5: peer_agreement | E5: 2
A6: 1 | B6: A11 | C6: =VLOOKUP(B6, ranking!A:B, 2, FALSE) -> A single dataset can be used to represent the proportion of irrigated lands. | D6: influence | E6: 3
A7: 1 | B7: B31 | C7: =VLOOKUP(B7, ranking!A:B, 2, FALSE) -> A single number can represent the irrigation efficiency over a region or country. | D7: limitations | E7: 0
A8: 1 | B8: B31 | C8: =VLOOKUP(B8, ranking!A:B, 2, FALSE) -> A single number can represent the irrigation efficiency over a region or country. | D8: plausibility | E8: 0
A9: 1 | B9: B31 | C9: =VLOOKUP(B9, ranking!A:B, 2, FALSE) -> A single number can represent the irrigation efficiency over a region or country. | D9: choice_space | E9: 3
A10: 1 | B10: B31 | C10: =VLOOKUP(B10, ranking!A:B, 2, FALSE) -> A single number can represent the irrigation efficiency over a region or country. | D10: peer_agreement | E10: 2
A11: 1 | B11: B31 | C11: =VLOOKUP(B11, ranking!A:B, 2, FALSE) -> A single number can represent the irrigation efficiency over a region or country. | D11: influence | E11: 3
A12: 1 | B12: A10 | C12: =VLOOKUP(B12, ranking!A:B, 2, FALSE) -> A single dataset can be used to represent the distribution of crop types. | D12: limitations | E12: 1
A13: 1 | B13: A10 | C13: =VLOOKUP(B13, ranking!A:B, 2, FALSE) -> A single dataset can be used to represent the distribution of crop types. | D13: plausibility | E13: 2
... A365: 8 | B365: A10 | C365: =VLOOKUP(B365, ranking!A:B, 2, FALSE) -> A single dataset can be used to represent the distribution of crop types. | D365: peer_agreement | E365: 3
A366: 8 | B366: A10 | C366: =VLOOKUP(B366, ranking!A:B, 2, FALSE) -> A single dataset can be used to represent the distribution of crop types. | D366: influence
A367: 8 | B367: C12 | C367: =VLOOKUP(B367, ranking!A:B, 2, FALSE) -> Crops in irrigated areas always receive their full water requirement. | D367: limitations | E367: 2
A368: 8 | B368: C12 | C368: =VLOOKUP(B368, ranking!A:B, 2, FALSE) -> Crops in irrigated areas always receive their full water requirement. | D368: plausibility | E368: 0
A369: 8 | B369: C12 | C369: =VLOOKUP(B369, ranking!A:B, 2, FALSE) -> Crops in irrigated areas always receive their full water requirement. | D369: choice_space | E369: 0
A370: 8 | B370: C12 | C370: =VLOOKUP(B370, ranking!A:B, 2, FALSE) -> Crops in irrigated areas always receive their full water requirement. | D370: peer_agreement | E370: 1
A371: 8 | B371: C12 | C371: =VLOOKUP(B371, ranking!A:B, 2, FALSE) -> Crops in irrigated areas always receive their full water requirement. | D371: influence | E371: 3
A372: 8 | B372: B22 | C372: =VLOOKUP(B372, ranking!A:B, 2, FALSE) -> Irrigation delivery is efficient. | D372: limitations | E372: 2
A373: 8 | B373: B22 | C373: =VLOOKUP(B373, ranking!A:B, 2, FALSE) -> Irrigation delivery is efficient. | D373: plausibility | E373: 0
A374: 8 | B374: B22 | C374: =VLOOKUP(B374, ranking!A:B, 2, FALSE) -> Irrigation delivery is efficient. | D374: choice_space | E374: 0
A375: 8 | B375: B22 | C375: =VLOOKUP(B375, ranking!A:B, 2, FALSE) -> Irrigation delivery is efficient. | D375: peer_agreement | E375: 2
A376: 8 | B376: B22 | C376: =VLOOKUP(B376, ranking!A:B, 2, FALSE) -> Irrigation delivery is efficient. | D376: influence | E376: 3
A377: 8 | B377: E2 | C377: =VLOOKUP(B377, ranking!A:B, 2, FALSE) -> Water supply for irrigation is unconstrained; unlimited to meet irrigation demand. | D377: limitations | E377: 1
A378: 8 | B378: E2 | C378: =VLOOKUP(B378, ranking!A:B, 2, FALSE) -> Water supply for irrigation is unconstrained; unlimited to meet irrigation demand. | D378: plausibility | E378: 1
... A801: 16 | B801: B31 | C801: =VLOOKUP(B801, ranking!A:B, 2, FALSE) -> A single number can represent the irrigation efficiency over a region or country. | D801: influence | E801: 0
A802: 17 | B802: C1 | C802: =VLOOKUP(B802, ranking!A:B, 2, FALSE) -> Soil properties are uniform for all land types. | D802: limitations
A803: 17 | B803: C1 | C803: =VLOOKUP(B803, ranking!A:B, 2, FALSE) -> Soil properties are uniform for all land types. | D803: plausibility | E803: 0
A804: 17 | B804: C1 | C804: =VLOOKUP(B804, ranking!A:B, 2, FALSE) -> Soil properties are uniform for all land types. | D804: choice_space | E804: 0
A805: 17 | B805: C1 | C805: =VLOOKUP(B805, ranking!A:B, 2, FALSE) -> Soil properties are uniform for all land types. | D805: peer_agreement | E805: 0
A806: 17 | B806: C1 | C806: =VLOOKUP(B806, ranking!A:B, 2, FALSE) -> Soil properties are uniform for all land types. | D806: influence | E806: 3
A807: 17 | B807: E1 | C807: =VLOOKUP(B807, ranking!A:B, 2, FALSE) -> Water supply for irrigation is constrained to local sources. | D807: limitations
A808: 17 | B808: E1 | C808: =VLOOKUP(B808, ranking!A:B, 2, FALSE) -> Water supply for irrigation is constrained to local sources. | D808: plausibility | E808: 0
A809: 17 | B809: E1 | C809: =VLOOKUP(B809, ranking!A:B, 2, FALSE) -> Water supply for irrigation is constrained to local sources. | D809: choice_space | E809: 0
A810: 17 | B810: E1 | C810: =VLOOKUP(B810, ranking!A:B, 2, FALSE) -> Water supply for irrigation is constrained to local sources. | D810: peer_agreement | E810: 0
A811: 17 | B811: E1 | C811: =VLOOKUP(B811, ranking!A:B, 2, FALSE) -> Water supply for irrigation is constrained to local sources. | D811: influence | E811: 3
A812: 17 | B812: B14 | C812: =VLOOKUP(B812, ranking!A:B, 2, FALSE) -> Irrigation is applied using a single method (flooding or sprinklers). | D812: limitations
A813: 17 | B813: B14 | C813: =VLOOKUP(B813, ranking!A:B, 2, FALSE) -> Irrigation is applied using a single method (flooding or sprinklers). | D813: plausibility | E813: 0
...

Sheet model
A1: code | B1: assumption | C1: model
A2: a11 | B2: =VLOOKUP(A2, ranking!A:B, 2, FALSE) -> A single dataset can be used to represent the proportion of irrigated lands. | C2: CLM4.5
A3: a11 | B3: =VLOOKUP(A3, ranking!A:B, 2, FALSE) -> A single dataset can be used to represent the proportion of irrigated lands. | C3: H08
A4: a11 | B4: =VLOOKUP(A4, ranking!A:B, 2, FALSE) -> A single dataset can be used to represent the proportion of irrigated lands. | C4: LPJmL
A5: a11 | B5: =VLOOKUP(A5, ranking!A:B, 2, FALSE) -> A single dataset can be used to represent the proportion of irrigated lands. | C5: MATSIRO
A6: a11 | B6: =VLOOKUP(A6, ranking!A:B, 2, FALSE) -> A single dataset can be used to represent the proportion of irrigated lands. | C6: VIC
A7: a11 | B7: =VLOOKUP(A7, ranking!A:B, 2, FALSE) -> A single dataset can be used to represent the proportion of irrigated lands. | C7: WaterGAP
A8: a11 | B8: =VLOOKUP(A8, ranking!A:B, 2, FALSE) -> A single dataset can be used to represent the proportion of irrigated lands. | C8: WBMplus
A9: e2 | B9: =VLOOKUP(A9, ranking!A:B, 2, FALSE) -> Water supply for irrigation is unconstrained; unlimited to meet irrigation demand. | C9: H08
A10: e2 | B10: =VLOOKUP(A10, ranking!A:B, 2, FALSE) -> Water supply for irrigation is unconstrained; unlimited to meet irrigation demand. | C10: LPJmL
A11: e2 | B11: =VLOOKUP(A11, ranking!A:B, 2, FALSE) -> Water supply for irrigation is unconstrained; unlimited to meet irrigation demand. | C11: MATSIRO
A12: e2 | B12: =VLOOKUP(A12, ranking!A:B, 2, FALSE) -> Water supply for irrigation is unconstrained; unlimited to meet irrigation demand. | C12: PCR-GLOBWB
A13: e2 | B13: =VLOOKUP(A13, ranking!A:B, 2, FALSE) -> Water supply for irrigation is unconstrained; unlimited to meet irrigation demand. | C13: VIC
... A47: c1 | B47: =VLOOKUP(A47, ranking!A:B, 2, FALSE) -> Soil properties are uniform for all land types. | C47: VIC

Sheet nature
A1: code | B1: assumption | C1: nature
A2: A1 | B2: Irrigated crops can be represented as discrete crop types. | C2: empirical
A3: A2 | B3: Irrigated crops can be represented as rice and non-rice. | C3: pragmatic
A4: A3 | B4: Types of irrigated crops are limited to less than 10. | C4: pragmatic
A5: A4 | B5: An area with mixed cropping can be treated as an area with one single crop. | C5: pragmatic
A6: A5 | B6: Farmers select the cultivar best adapted to the local environment. | C6: pragmatic
A7: A6 | B7: Temperate cereals can be grown during summer. | C7: pragmatic
A8: A7 | B8: The primary crop is planted during the first season, followed by the secondary crop. | C8: pragmatic
A9: A8 | B9: Rice is grown twice per year. | C9: pragmatic
A10: A9 | B10: The same crops are grown in the same places every year. | C10: pragmatic
A11: A10 | B11: A single dataset can be used to represent the distribution of crop types. | C11: pragmatic
A12: A11 | B12: A single dataset can be used to represent the proportion of irrigated lands. | C12: pragmatic
... A101: E11 | B101: No fixed priority is given to any sector; instead, all sectors compete equally for available water. | C101: pragmatic
